/home/zhanda/miniconda3/envs/dazzle/lib/python3.9/site-packages/torch/distributed/launch.py:181: FutureWarning: The module torch.distributed.launch is deprecated
and will be removed in future. Use torchrun.
Note that --use-env is set by default in torchrun.
If your script expects `--local-rank` argument to be set, please
change it to read from `os.environ['LOCAL_RANK']` instead. See 
https://pytorch.org/docs/stable/distributed.html#launch-utility for 
further instructions

  warnings.warn(
[2024-05-07 16:34:52,411] torch.distributed.run: [WARNING] 
[2024-05-07 16:34:52,411] torch.distributed.run: [WARNING] *****************************************
[2024-05-07 16:34:52,411] torch.distributed.run: [WARNING] Setting OMP_NUM_THREADS environment variable for each process to be 1 in default, to avoid your system being overloaded, please further tune the variable for optimal performance in your application as needed. 
[2024-05-07 16:34:52,411] torch.distributed.run: [WARNING] *****************************************
Traceback (most recent call last):
  File "/home/zhanda/workspace/Dazzle/benchmark/superscaler/SuperScaler/runtime/pretrain_gpt.py", line 32, in <module>
    from megatron.data.gpt_dataset import build_train_valid_test_datasets
  File "/home/zhanda/workspace/Dazzle/benchmark/superscaler/SuperScaler/runtime/megatron/data/__init__.py", line 1, in <module>
    from . import indexed_dataset
  File "/home/zhanda/workspace/Dazzle/benchmark/superscaler/SuperScaler/runtime/megatron/data/indexed_dataset.py", line 98, in <module>
    6: np.float,
  File "/home/zhanda/miniconda3/envs/dazzle/lib/python3.9/site-packages/numpy/__init__.py", line 284, in __getattr__
    raise AttributeError("module {!r} has no attribute "
AttributeError: module 'numpy' has no attribute 'float'
Traceback (most recent call last):
  File "/home/zhanda/workspace/Dazzle/benchmark/superscaler/SuperScaler/runtime/pretrain_gpt.py", line 32, in <module>
    from megatron.data.gpt_dataset import build_train_valid_test_datasets
  File "/home/zhanda/workspace/Dazzle/benchmark/superscaler/SuperScaler/runtime/megatron/data/__init__.py", line 1, in <module>
    from . import indexed_dataset
  File "/home/zhanda/workspace/Dazzle/benchmark/superscaler/SuperScaler/runtime/megatron/data/indexed_dataset.py", line 98, in <module>
    6: np.float,
  File "/home/zhanda/miniconda3/envs/dazzle/lib/python3.9/site-packages/numpy/__init__.py", line 284, in __getattr__
    raise AttributeError("module {!r} has no attribute "
AttributeError: module 'numpy' has no attribute 'float'
[2024-05-07 16:34:57,444] torch.distributed.elastic.multiprocessing.api: [ERROR] failed (exitcode: 1) local_rank: 0 (pid: 1065089) of binary: /home/zhanda/miniconda3/envs/dazzle/bin/python3
Traceback (most recent call last):
  File "/home/zhanda/miniconda3/envs/dazzle/lib/python3.9/runpy.py", line 197, in _run_module_as_main
    return _run_code(code, main_globals, None,
  File "/home/zhanda/miniconda3/envs/dazzle/lib/python3.9/runpy.py", line 87, in _run_code
    exec(code, run_globals)
  File "/home/zhanda/miniconda3/envs/dazzle/lib/python3.9/site-packages/torch/distributed/launch.py", line 196, in <module>
    main()
  File "/home/zhanda/miniconda3/envs/dazzle/lib/python3.9/site-packages/torch/distributed/launch.py", line 192, in main
    launch(args)
  File "/home/zhanda/miniconda3/envs/dazzle/lib/python3.9/site-packages/torch/distributed/launch.py", line 177, in launch
    run(args)
  File "/home/zhanda/miniconda3/envs/dazzle/lib/python3.9/site-packages/torch/distributed/run.py", line 797, in run
    elastic_launch(
  File "/home/zhanda/miniconda3/envs/dazzle/lib/python3.9/site-packages/torch/distributed/launcher/api.py", line 134, in __call__
    return launch_agent(self._config, self._entrypoint, list(args))
  File "/home/zhanda/miniconda3/envs/dazzle/lib/python3.9/site-packages/torch/distributed/launcher/api.py", line 264, in launch_agent
    raise ChildFailedError(
torch.distributed.elastic.multiprocessing.errors.ChildFailedError: 
============================================================
pretrain_gpt.py FAILED
------------------------------------------------------------
Failures:
[1]:
  time      : 2024-05-07_16:34:57
  host      : zhanda-mist-0430-us-east4-c-1.us-east4-c.c.cohere-internal.internal
  rank      : 1 (local_rank: 1)
  exitcode  : 1 (pid: 1065090)
  error_file: <N/A>
  traceback : To enable traceback see: https://pytorch.org/docs/stable/elastic/errors.html
------------------------------------------------------------
Root Cause (first observed failure):
[0]:
  time      : 2024-05-07_16:34:57
  host      : zhanda-mist-0430-us-east4-c-1.us-east4-c.c.cohere-internal.internal
  rank      : 0 (local_rank: 0)
  exitcode  : 1 (pid: 1065089)
  error_file: <N/A>
  traceback : To enable traceback see: https://pytorch.org/docs/stable/elastic/errors.html
============================================================
